Workbook

Sheet Inputs
A1: length | B1: width | C1: depth
A2: 1 | B2: 1 | C2: 1

Sheet Roof Slab
A1: DESIGN OF ROOF SLAB
A3: A:INPUT DATA
A5: Description | B5: Symbol | C5: Value | D5: Unit
A6: Tank Length (Long Span) | B6: Ly | C6: =Inputs!A2 -> 1 | D6: m
A7: Tank Width (Short Span) | B7: Lx | C7: =Inputs!B2 -> 1 | D7: m
A8: Edge Condition | B8: - | C8: Fixed on all edges | D8: -
A9: Grade of Concrete | B9: fck | C9: 30 | D9: MPa
A10: Grade of Steel | B10: fy | C10: 500 | D10: MPa
A11: Clear Cover | B11: Cc | C11: 50 | D11: mm
A12: Live Load | B12: LL | C12: 3 | D12: kN/m²
A13: Finish/Waterproofing | B13: FL | C13: 1 | D13: kN/m²
A14: Bar Diameter (Main) | B14: φm | C14: 16 | D14: mm
A15: Bar Diameter (Dist.) | B15: φd | C15: 12 | D15: mm
A17: B.PRELIMINARY SIZING
A19: Short Span/Long Span | B19: Lx/Ly | C19: =C7/C6 -> 1 | D19: -
A20: Assumed Span/Depth Ratio | B20: - | C20: 28 | D20: -
A21: Required Depth | B21: d | C21: =MROUND(C7*1000/C20,50) -> 50 | D21: mm
A22: Assumed Overall Depth | B22: D | C22: =MAX(150,ROUNDUP(C21/10,0)*10+50) -> 150 | D22: mm
A23: Effective Depth (Short Span) | B23: dx | C23: =C22-C11-C14/2 -> 92 | D23: mm
A24: Effective Depth (Long Span) | B24: dy | C24: =C22-C11-C14-C15/2 -> 78 | D24: mm
A26: C.LOAD CALCULATIONS
A28: Self Weight (DL) | B28: DL | C28: =(C22/1000)*25 -> 3.75 | D28: kN/m²
A29: Finish/Waterproofing | B29: FL | C29: =C13 -> 1 | D29: kN/m²
A30: Live Load | B30: LL | C30: =C12 -> 3 | D30: kN/m²
A31: Total Service Load | B31: w | C31: =C28+C29+C30 -> 7.75 | D31: kN/m²
A32: Factored Loads:
A33: Dead Load Factor | B33: γDL | C33: 1.5 | D33: -
A34: Live Load Factor | B34: γLL | C34: 1.5 | D34: -
A35: Factored DL | B35: wDL | C35: =(C28+C29)*C33 -> 7.125 | D35: kN/m²
A36: Factored LL | B36: wLL | C36: =C30*C34 -> 4.5 | D36: kN/m²
A37: Total Factored Load | B37: wu | C37: =C35+C36 -> 11.625 | D37: kN/m²
A39: D.LOAD TRANSFER TO WALLS
A41: Total Roof Load (Factored) | B41: Wroof | C41: =C37*C6*C7 -> 11.625 | D41: kN
A42: Load on Long Walls
A43: Tributary Area per Long Wall | B43: Atr,long | C43: =C7/2*C6 -> 0.5 | D43: m²
A44: Load per Long Wall | B44: Wlong | C44: =C37*C43 -> 5.8125 | D44: kN
A45: Load per meter on Long Wall | B45: wlong | C45: =C44/C6 -> 5.8125 | D45: kN/m
A46: Load on Short Walls
A47: Tributary Area per Short Wall | B47: Atr,short | C47: =C6/2*C7 -> 0.5 | D47: m²
A48: Load per Short Wall | B48: Wshort | C48: =C37*C47 -> 5.8125 | D48: kN
...

Sheet Long Wall
A1: DESIGN OF LONG WALL
A3: A:INPUT DATA
A5: Description | B5: Symbol | C5: Value | D5: Unit
A6: Length of Wall | B6: L | C6: =Inputs!A2 -> 1 | D6: m
A7: Height of Wall | B7: H | C7: =Inputs!C2 -> 1 | D7: m
A8: Water Depth Inside | B8: Hw | C8: =C7-0.5 -> 0.5 | D8: m
A9: Soil Height Outside | B9: Hs | C9: =C7 -> 1 | D9: m
A10: Support Condition | B10: - | C10: Fixed Top & Bottom | D10: -
A11: Grade of Concrete | B11: fck | C11: 30 | D11: MPa
A12: Grade of Steel | B12: fy | C12: 500 | D12: MPa
A13: Clear Cover (Inside) | B13: Cci | C13: 50 | D13: mm
A14: Clear Cover (Outside) | B14: Cco | C14: 50 | D14: mm
A15: Density of Water | B15: γw | C15: 10 | D15: kN/m³
A16: Density of Soil | B16: γs | C16: 18 | D16: kN/m³
A17: Coeff. of Earth Pressure | B17: Ka | C17: 0.33 | D17: -
A18: Bar Diameter (Main) | B18: φm | C18: 16 | D18: mm
A19: Bar Diameter (Dist.) | B19: φd | C19: 12 | D19: mm
A21: Load per meter from Roof | B21: wroof | C21: ='Roof Slab'!B161 -> 5.8125 | D21: kN/m
A23: B. PRELIMINARY SIZING
A24: Minimum Wall Thickness | B24: tw,min | C24: =MROUND(MAX(300,C7*1000/12),50) -> 300 | D24: mm
A25: Assumed Wall Thickness | B25: tw | C25: =ROUNDUP(C24/10,0)*10 -> 300 | D25: mm
A26: Effective Depth (Inside Face) | B26: di | C26: =C25-C13-C18/2 -> 242 | D26: mm
A27: Effective Depth (Outside Face) | B27: do | C27: =C25-C14-C18/2 -> 242 | D27: mm
A28: Eff. Cover (Inside) | B28: d'i | C28: =C13+C18/2 -> 58 | D28: mm
A29: Eff. Cover (Outside) | B29: d'o | C29: =C14+C18/2 -> 58 | D29: mm
A31: C. LOAD CALCULATIONS
A33: VERTICAL LOAD (Top of Wall)
A34: Roof Slab Load (Factored) | B34: Proof | C34: =C21 -> 5.8125 | D34: kN/m
A35: WATER PRESSURE (INSIDE)- Full Condition
A36: Max Water Pressure at Base | B36: Pw,max | C36: =C8*C15 -> 5 | D36: kN/m²
A37: Load Factor for Water | B37: γw | C37: 1.5 | D37: -
A38: Design Water Pressure | B38: Pw,d | C38: =C36*C37 -> 7.5 | D38: kN/m²
A39: SOIL PRESSURE (OUTSIDE) - Empty Condition
A40: Active Earth Pressure at Base | B40: Ps,max | C40: =C9*C16*C17 -> 5.94 | D40: kN/m²
A41: Load Factor for Soil | B41: γs | C41: 1.5 | D41: -
A42: Design Soil Pressure | B42: Ps,d | C42: =C40*C41 -> 8.91 | D42: kN/m²
A44: CRITICAL LOAD CASE
A45: Case 1: Tank Full (Water Inside) | B45: P1 | C45: =C38 -> 7.5 | D45: kN/m²
A46: Case 2: Tank Empty (Soil Outside) | B46: P2 | C46: =C42 -> 8.91 | D46: kN/m²
A47: Critical Pressure | B47: Pcr | C47: =MAX(C45,C46) -> 8.91 | D47: kN/m²
...

Sheet Short Wall
A1: DESIGN OF SHORT WALL
A3: A.INPUT DATA
A5: Description | B5: Symbol | C5: Value | D5: Unit
A6: Length of Wall | B6: L | C6: =Inputs!B2 -> 1 | D6: m
A7: Height of Wall | B7: H | C7: =Inputs!C2 -> 1 | D7: m
A8: Water Depth Inside | B8: Hw | C8: =C7-0.5 -> 0.5 | D8: m
A9: Soil Height Outside | B9: Hs | C9: =C7 -> 1 | D9: m
A10: Support Condition | B10: - | C10: Fixed Top, Bottom & Sides | D10: -
A11: Grade of Concrete | B11: fck | C11: 30 | D11: MPa
A12: Grade of Steel | B12: fy | C12: 500 | D12: MPa
A13: Clear Cover (Inside) | B13: Cci | C13: 50 | D13: mm
A14: Clear Cover (Outside) | B14: Cco | C14: 50 | D14: mm
A15: Density of Water | B15: γw | C15: 10 | D15: kN/m³
A16: Density of Soil | B16: γs | C16: 18 | D16: kN/m³
A17: Coeff. of Earth Pressure | B17: Ka | C17: 0.33 | D17: -
A18: Bar Diameter (Main) | B18: φm | C18: 16 | D18: mm
A19: Bar Diameter (Dist.) | B19: φd | C19: 12 | D19: mm
A21: Load per meter from Roof | B21: wroof | C21: ='Roof Slab'!B162 -> 5.8125 | D21: kN/m
A23: B.PRELIMINARY SIZING
A25: Minimum Wall Thickness | B25: tw,min | C25: =MROUND(MAX(300,C7*1000/12),50) -> 300 | D25: mm
A26: Assumed Wall Thickness | B26: tw | C26: =ROUNDUP(C25/10,0)*10 -> 300 | D26: mm
A27: Effective Depth (Inside Face) | B27: di | C27: =C26-C13-C18/2 -> 242 | D27: mm
A28: Effective Depth (Outside Face) | B28: do | C28: =C26-C14-C18/2 -> 242 | D28: mm
A29: Eff. Cover (Inside) | B29: d'i | C29: =C13+C18/2 -> 58 | D29: mm
A30: Eff. Cover (Outside) | B30: d'o | C30: =C14+C18/2 -> 58 | D30: mm
A33: C.LOAD CALCULATIONS
A35: VERTICAL LOAD (Top of Wall)
A36: Roof Slab Load (Factored) | B36: Proof | C36: =C21 -> 5.8125 | D36: kN/m
A37: WATER PRESSURE (INSIDE) - Full Condition
A38: Max Water Pressure at Base | B38: Pw,max | C38: =C8*C15 -> 5 | D38: kN/m²
A39: Load Factor for Water | B39: γw | C39: 1.5 | D39: -
A40: Design Water Pressure | B40: Pw,d | C40: =C38*C39 -> 7.5 | D40: kN/m²
A41: SOIL PRESSURE (OUTSIDE) - Empty Condition
A42: Active Earth Pressure at Base | B42: Ps,max | C42: =C9*C16*C17 -> 5.94 | D42: kN/m²
A43: Load Factor for Soil | B43: γs | C43: 1.5 | D43: -
A44: Design Soil Pressure | B44: Ps,d | C44: =C42*C43 -> 8.91 | D44: kN/m²
A46: CRITICAL LOAD CASE
A47: Case 1: Tank Full (Water Inside) | B47: P1 | C47: =C40 -> 7.5 | D47: kN/m²
A48: Case 2: Tank Empty (Soil Outside) | B48: P2 | C48: =C44 -> 8.91 | D48: kN/m²
A49: Critical Pressure | B49: Pcr | C49: =MAX(C47,C48) -> 8.91 | D49: kN/m²
...

Sheet Base Slab
A1: DESIGN OF BASE SLAB
A3: A.INPUT DATA
A5: Description | B5: Symbol | C5: Value | D5: Unit
A6: Tank Length | B6: Ly | C6: =Inputs!A2 -> 1 | D6: m
A7: Tank Width | B7: Lx | C7: =Inputs!B2 -> 1 | D7: m
A8: Tank Height | B8: H | C8: =Inputs!C2 -> 1 | D8: m
A9: Water Depth | B9: Hw | C9: =C8-0.5 -> 0.5 | D9: m
A10: Edge Condition | B10: - | C10: Fixed on all edges | D10: -
A11: Grade of Concrete | B11: fck | C11: 30 | D11: MPa
A12: Grade of Steel | B12: fy | C12: 500 | D12: MPa
A13: Clear Cover | B13: Cc | C13: 75 | D13: mm
A14: Soil Bearing Capacity | B14: SBC | C14: 150 | D14: kN/m²
A15: Bar Diameter (Main) | B15: φm | C15: 25 | D15: mm
A16: Bar Diameter (Dist.) | B16: φd | C16: 16 | D16: mm
A17: Ground Water Level | B17: GWL | C17: 3 | D17: m
A18: LOADS FROM WALLS:
A19: Load from Long Wall (per m) | B19: wlong | C19: ='Long Wall'!B178 -> 13.3125 | D19: kN/m
A20: Load from Short Wall (per m) | B20: wshort | C20: ='Short Wall'!B195 -> 13.3125 | D20: kN/m
A21: Long Wall Thickness | B21: tlong | C21: ='Long Wall'!C92 -> 300 | D21: mm
A22: Short Wall Thickness | B22: tshort | C22: ='Short Wall'!C135 -> 300 | D22: mm
A24: B.PRELIMINARY SIZING
A26: Short Span/Long Span | B26: Lx/Ly | C26: =C7/C6 -> 1 | D26: -
A27: Assumed Span/Depth Ratio | B27: - | C27: 25 | D27: -
A28: Required Depth | B28: d | C28: 500 | D28: mm
A29: Assumed Overall Depth | B29: D | C29: =MROUND(ROUNDUP(C28/10,0)*10+75,50) -> 600 | D29: mm
A30: Effective Depth (Short Span) | B30: dx | C30: =C29-C13-C15/2 -> 512.5 | D30: mm
A31: Effective Depth (Long Span) | B31: dy | C31: =C29-C13-C15-C16/2 -> 492 | D31: mm
A34: C.LOAD CALCULATIONS
A36: DOWNWARD LOADS
A37: Self Weight of Base Slab | B37: DL1 | C37: =(C29/1000)*25 -> 15 | D37: kN/m²
A38: Weight of Water | B38: DL2 | C38: =C9*10 -> 5 | D38: kN/m²
A39: Loads from Walls (Distributed over base area)
A40: Total Load from Long Walls | B40: Wlong,total | C40: =C19*C6*2 -> 26.625 | D40: kN
A41: Distributed over Base | B41: wlong,dist | C41: =C40/(C6*C7) -> 26.625 | D41: kN/m²
A42: Total Load from Short Walls | B42: Wshort,total | C42: =C20*C7*2 -> 26.625 | D42: kN
A43: Distributed over Base | B43: wshort,dist | C43: =C42/(C6*C7) -> 26.625 | D43: kN/m²
A44: Total Wall Load | B44: DL3 | C44: =C41+C43 -> 53.25 | D44: kN/m²
A45: Total Dead Load | B45: DL | C45: =C37+C38+C44 -> 73.25 | D45: kN/m²
A46: UPWARD LOADS
A47: Upward Water Pressure (if GWL high) | B47: Up | C47: =IF(C17<C8,10*(C17-C8),0) -> 0 | D47: kN/m²
...

Sheet Estimation
A1: ESTIMATION OF TANK
A4: A.INPUT DATA
A6: Tank Specifications:
A7: Description | B7: Value | C7: Unit
A8: Internal Length | B8: =Inputs!A2 -> 1 | C8: m
A9: Internal Width | B9: =Inputs!B2 -> 1 | C9: m
A10: Internal Height | B10: =Inputs!C2 -> 1 | C10: m
A11: Tank Volume | B11: =B8*B9*B10 -> 1 | C11: m³
A12: Capacity | B12: =B11*1000 -> 1000 | C12: liters
A13: Capacity (KL) | B13: =B12/1000 -> 1 | C13: KL
A15: Member Dimensions:
A16: Member | B16: Thickness (mm) | C16: Thickness (m)
A17: Roof Slab | B17: ='Roof Slab'!B148 -> 150 | C17: =B17/1000 -> 0.15
A18: Base Slab | B18: ='Base Slab'!B197 -> 600 | C18: =B18/1000 -> 0.6
A19: Long Wall | B19: ='Long Wall'!C92 -> 300 | C19: =B19/1000 -> 0.3
A20: Short Wall | B20: ='Short Wall'!C135 -> 300 | C20: =B20/1000 -> 0.3
A22: B.QUANTITY CALCULATIONS
A24: Description | B24: Length(m) | C24: Width(m) | D24: Height(m) | E24: Quantity | F24: Unit | G24: Remarks
A25: 1.EarthWork
A26: Excavation in ordinary soil | B26: =B8+1 -> 2 | C26: =B9+1 -> 2 | D26: 3.5 | E26: =B26*C26*D26 -> 14 | F26: m³ | G26: Add 0.5m working space
A27: Filling with excavated earth | B27: =B26 -> 2 | C27: =C26 -> 2 | D27: 0.5 | E27: =B27*C27*D27 -> 2 | F27: m³ | G27: Around tank
A28: Disposal of excess earth | B28: - | C28: - | D28: - | E28: =E26-E27 -> 12 | F28: m³ | G28: Excess removal
A29: 2.RCC Quantities
A30: Base Slab | B30: =B8 -> 1 | C30: =B9 -> 1 | D30: =C18 -> 0.6 | E30: =B30*C30*D30 -> 0.6 | F30: m³
A31: Long Walls (2 nos) | B31: =B8*2 -> 2 | C31: - | D31: =B10*C19 -> 0.3 | E31: =B31*D31 -> 0.6 | F31: m³ | G31: Two walls
A32: Short Walls (2 nos) | B32: =B9*2 -> 2 | C32: - | D32: =B10*C20 -> 0.3 | E32: =B32*D32 -> 0.6 | F32: m³ | G32: Two walls
A33: Roof Slab | B33: =B8 -> 1 | C33: =B9 -> 1 | D33: =C17 -> 0.15 | E33: =B33*C33*D33 -> 0.15 | F33: m³
A34: Total RCC Concrete | E34: =SUM(E30:E33) -> 1.95 | F34: m³
A35: Add 2% wastage | E35: =E34*0.02 -> 0.039 | F35: m³
A36: Total Concrete Required | E36: =E34+E35 -> 1.989 | F36: m³ | G36: FINAL
A37: 3.Steel Quantites
A38: Base Slab Steel | E38: =E30*120 -> 72 | F38: kg | G38: @ 120 kg/m³
A39: Wall Steel | E39: =(E31+E32)*110 -> 132 | F39: kg | G39: @ 110 kg/m³
A40: Roof Slab Steel | E40: =E33*100 -> 15 | F40: kg | G40: @ 100 kg/m³
A41: Total Steel Required | E41: =SUM(E38:E40) -> 219 | F41: kg
A42: Add 10% wastage | E42: =E41*0.1 -> 21.9 | F42: kg
A43: Total Steel | E43: =E41+E42 -> 240.9 | F43: kg | G43: FINAL
A44: Convert to Tonnes | E44: =E43/1000 -> 0.2409 | F44: Tonnes | G44: For Costing
A45: 4.FormWork Quantities
A46: Base Slab - Top surface | B46: =B8 -> 1 | C46: =B9 -> 1 | D46: - | E46: =B46*C46 -> 1 | F46: m²
...

Sheet Final Values
A1: Internal Length | B1: Internal Width | C1: Internal Height | D1: RB Overall Depth | E1: RB Short Span - Top | F1: RB Short Span - Bottom | G1: RB Long Span - Top | H1: RB Long Span - Bottom | I1: RB Shear Check | J1: RB Deflection Check | K1: RB Crack Width Check | L1: Long Wall Thickness | M1: LW Vertical - Inside Face | N1: LW Vertical - Outside Face | O1: LW Horizontal - Both Faces | P1: LW Axial Load Check | Q1: LW Shear Check | R1: LW Crack Width Check | S1: Short Wall Thickness | T1: SW Vertical - Inside Face | U1: SW Vertical - Outside Face | V1: SW Horizontal - Inside Face | W1: SW Horizontal - Outside Face | X1: SW Axial Load Check | Y1: SW Shear Check | Z1: SW Crack Width Check | AA1: Base Slab Overall Depth | AB1: BS Short Span - Bottom | AC1: BS Short Span - Top | AD1: BS Long Span - Bottom | AE1: BS Long Span - Top | AF1: BS Bearing Capacity Check | AG1: BS Uplift Check | AH1: BS Shear Check | AI1: BS Punching Shear (Long Wall) | AJ1: BS Punching Shear (Short Wall) | AK1: BS Crack Width Check | AL1: 1.EarthWork | AM1: 2.Reinforced Cement Concrete | AN1: 3.Steel Reinforcement | AO1: 4.Formwork | AP1: 5.WaterProofing Works | AQ1: 6.Plastering Works | AR1: 7.Plumbing & Fixtures | AS1: 8.Contractor's Profit (10%) | AT1: 9.Contingency (5%) | AU1: 10.GST @ 18% | AV1: TOTAL COST(₹)
A2: =Inputs!A2&"m" -> 1m | B2: =Inputs!B2&"m" -> 1m | C2: =Inputs!C2&"m" -> 1m | D2: ='Roof Slab'!B148&"mm" -> 150mm | E2: ='Roof Slab'!C14&"mm φ @ "&'Roof Slab'!C79&" mm c/c" -> 16mm φ @ 300 mm c/c | F2: ='Roof Slab'!C14&"mm φ @ "&'Roof Slab'!C85&" mm c/c" -> 16mm φ @ 300 mm c/c | G2: ='Roof Slab'!C15&"mm φ @ "&'Roof Slab'!C105&" mm c/c" -> 12mm φ @ 250 mm c/c | H2: ='Roof Slab'!C15&"mm φ @ "&'Roof Slab'!C111&" mm c/c" -> 12mm φ @ 250 mm c/c | I2: ='Roof Slab'!C128 -> SAFE | J2: ='Roof Slab'!B157 -> OK | K2: ='Roof Slab'!B158 -> OK | L2: ='Long Wall'!B165&"mm" -> 300mm | M2: ='Long Wall'!C18&"mm φ @ "&'Long Wall'!C92&" mm c/c" -> 16mm φ @ 300 mm c/c | N2: ='Long Wall'!C18&"mm φ @ "&'Long Wall'!C104&" mm c/c" -> 16mm φ @ 300 mm c/c | O2: ='Long Wall'!C19&"mm φ @ "&'Long Wall'!C116&" mm c/c" -> 12mm φ @ 300 mm c/c | P2: ='Long Wall'!B173 -> OK - Primarily Flexure | Q2: ='Long Wall'!B174 -> SAFE | R2: ='Long Wall'!B175 -> OK | S2: ='Long Wall'!B165&"mm" -> 300mm | T2: ='Long Wall'!C18&"mm φ @ "&'Long Wall'!C92&" mm c/c" -> 16mm φ @ 300 mm c/c | U2: ='Short Wall'!C18&"mm φ @ "&'Short Wall'!C106&" mm c/c" -> 16mm φ @ 300 mm c/c | V2: ='Short Wall'!C19&"mm φ @ "&'Short Wall'!C123&" mm c/c" -> 12mm φ @ 300 mm c/c | W2: ='Short Wall'!C19&"mm φ @ "&'Short Wall'!C135&" mm c/c" -> 12mm φ @ 300 mm c/c | X2: ='Short Wall'!B190 -> OK - Primarily Flexure | Y2: ='Short Wall'!B191 -> SAFE | Z2: ='Short Wall'!B192 -> OK | AA2: ='Base Slab'!B197&"mm" -> 600mm | AB2: ='Base Slab'!C15&"mm φ @ "&'Base Slab'!C117&" mm c/c" -> 25mm φ @ 300 mm c/c | AC2: ='Base Slab'!C15&"mm φ @ "&'Base Slab'!C122&" mm c/c" -> 25mm φ @ 300 mm c/c | AD2: ='Base Slab'!C16&"mm φ @ "&'Base Slab'!C142&" mm c/c" -> 16mm φ @ 300 mm c/c | AE2: ='Base Slab'!C16&"mm φ @ "&'Base Slab'!C147&" mm c/c" -> 16mm φ @ 300 mm c/c | AF2: ='Base Slab'!B219 -> OK | AG2: ='Base Slab'!B220 -> SAFE | AH2: ='Base Slab'!B221 -> SAFE | AI2: ='Base Slab'!B222 -> SAFE | AJ2: ='Base Slab'!B223 -> SAFE | AK2: ='Base Slab'!B224 -> OK | AL2: =Estimation!B123 -> 2560 | AM2: =Estimation!B124 -> 14917.5 | AN2: =Estimation!B125 -> 15658.5 | AO2: =Estimation!B126 -> 5175 | AP2: =Estimation!B127 -> 2300 | AQ2: =Estimation!B128 -> 1720 | AR2: =Estimation!B129 -> 10600 | AS2: =Estimation!B130 -> 5293.1 | AT2: =Estimation!B131 -> 2911.205 | AU2: =Estimation!B132 -> 11004.355 | AV2: =Estimation!B133 -> 72139.66
